Workbook
Name NativeTimeline_Order_Date: #N/A
Name Slicer_Gender: #N/A
Name Slicer_Region: #N/A

Sheet Adidas-US-Interactive-Sales-Pro
A1: Order_ID | B1: Order_Date | C1: SKU | D1: Product_Name | E1: Category | F1: Region | G1: Store_Type | H1: Units_Sold | I1: Unit_Price | J1: Discount | K1: Total Sales | L1: Profit | M1: Customer_Age | N1: Gender | O1: Payment_Method | P1: Retails
A2: 101178 | B2: 45556 | C2: AD-1877-D | D2: Tiro 23 Track Pants | E2: Apparel | F2: Egypt | G2: Online | H2: 5 | I2: 49.68 | J2: 0 | K2: 248.4 | L2: 70.4 | M2: 35 | N2: Female | O2: NetBanking | P2: Amazon
A3: 100865 | B3: 45539 | C3: AD-1745-B | D3: Essentials Tee | E3: Apparel | F3: Oman | G3: Online | H3: 2 | I3: 27.07 | J3: 0 | K3: 54.14 | L3: 11.35 | M3: 48 | N3: Female | O3: NetBanking | P3: Walmart
A4: 100101 | B4: 45559 | C4: AD-8110-A | D4: Superstar | E4: Footwear | F4: Egypt | G4: Online | H4: 3 | I4: 96.58 | J4: 20 | K4: 231.79 | L4: 61.86 | M4: 34 | N4: Male | O4: Debit Card | P4: Foot Locker
A5: 100439 | B5: 45294 | C5: AD-4892-C | D5: Performance Socks (3-pack) | E5: Accessories | F5: KSA | G5: Retail | H5: 5 | I5: 17.49 | J5: 10 | K5: 78.7 | L5: 35.99 | M5: 30 | N5: Female | O5: Apple Pay
A6: 100058 | B6: 45206 | C6: AD-8657-B | D6: Originals Backpack | E6: Accessories | F6: Oman | G6: Retail | H6: 3 | I6: 58.96 | J6: 5 | K6: 168.04 | L6: 68.38 | M6: 30 | N6: Female | O6: PayPal
A7: 101120 | B7: 45595 | C7: AD-5267-A | D7: Adicolor Hoodie | E7: Apparel | F7: Oman | G7: Online | H7: 1 | I7: 72.5 | J7: 5 | K7: 68.88 | L7: 16.65 | M7: 32 | N7: Female | O7: Apple Pay
A8: 100323 | B8: 45049 | C8: AD-3735-C | D8: Ultraboost 22 | E8: Footwear | F8: Egypt | G8: Online | H8: 4 | I8: 182.16 | J8: 0 | K8: 728.64 | L8: 227.81 | M8: 29 | N8: Female | O8: NetBanking
A9: 100974 | B9: 45283 | C9: AD-7305-C | D9: Originals Backpack | E9: Accessories | F9: Lebanon | G9: Retail | H9: 3 | I9: 57.19 | J9: 0 | K9: 171.57 | L9: 52.43 | M9: 49 | N9: Female | O9: Debit Card
A10: 100411 | B10: 45229 | C10: AD-4842-A | D10: Copa Sense | E10: Footwear | F10: Oman | G10: Online | H10: 3 | I10: 152.09 | J10: 10 | K10: 410.64 | L10: 93.96 | M10: 27 | N10: Female | O10: Cash
A11: 100855 | B11: 45050 | C11: AD-2386-C | D11: Sports Bottle | E11: Accessories | F11: Iraq | G11: Retail | H11: 1 | I11: 15.26 | J11: 20 | K11: 12.21 | L11: 3.82 | M11: 33 | N11: Male | O11: Google Pay
A12: 100820 | B12: 45279 | C12: AD-3148-C | D12: Performance Socks (3-pack) | E12: Accessories | F12: Iraq | G12: Outlet | H12: 1 | I12: 18.61 | J12: 20 | K12: 14.89 | L12: 6.07 | M12: 25 | N12: Male | O12: Google Pay
A13: 100044 | B13: 45459 | C13: AD-2146-C | D13: Sports Bottle | E13: Accessories | F13: Lebanon | G13: Retail | H13: 1 | I13: 14.47 | J13: 0 | K13: 14.47 | L13: 3.08 | M13: 34 | N13: Male | O13: Apple Pay
A14: 100049 | B14: 45022 | C14: AD-8784-A | D14: Adicolor Hoodie | E14: Apparel | F14: Iraq | G14: Online | H14: 2 | I14: 64.26 | J14: 0 | K14: 128.52 | L14: 48.57 | M14: 18 | N14: Male | O14: UPI
A15: 100849 | B15: 45114 | C15: AD-6074-D | D15: Training Cap | E15: Accessories | F15: Oman | G15: Online | H15: 5 | I15: 21.03 | J15: 10 | K15: 94.64 | L15: 38.46 | M15: 39 | N15: Male | O15: Google Pay
A16: 100240 | B16: 45376 | C16: AD-4836-C | D16: Adicolor Hoodie | E16: Apparel | F16: Egypt | G16: Retail | H16: 2 | I16: 64.45 | J16: 0 | K16: 128.9 | L16: 40.96 | M16: 42 | N16: Male | O16: NetBanking
... A1201: 101126 | B1201: 45875 | C1201: AD-4543-C | D1201: Stan Smith | E1201: Footwear | F1201: Iraq | G1201: Online | H1201: 6 | I1201: 72.03 | J1201: 20 | K1201: 345.74 | L1201: 94.24 | M1201: 31 | N1201: Male | O1201: PayPal

Sheet Sheet1
A1: Order_ID | B1: Order_Date | C1: SKU | D1: Product_Name | E1: Category | F1: Region | G1: Store_Type | H1: Units_Sold | I1: Unit_Price | J1: Discount | K1: Revenue | L1: Profit | M1: Total Profit | N1: Customer_Age | O1: Gender | P1: Payment_Method
A2: 101126 | B2: 45875 | C2: AD-4543-C | D2: Stan Smith | E2: Footwear | F2: Iraq | G2: Online | H2: 6 | I2: 72.03 | J2: 20 | K2: 345.74 | L2: 94.24 | M2: 565.44 | N2: 31 | O2: Male | P2: PayPal
A3: 100860 | B3: 45172 | C3: AD-5412-A | D3: NMD_R1 | E3: Footwear | F3: Oman | G3: Retail | H3: 4 | I3: 142.77 | J3: 0 | K3: 571.08 | L3: 170.99 | M3: 683.96 | N3: 40 | O3: Male | P3: Debit Card
A4: 100101 | B4: 45559 | C4: AD-8110-A | D4: Superstar | E4: Footwear | F4: Egypt | G4: Online | H4: 3 | I4: 96.58 | J4: 20 | K4: 231.79 | L4: 61.86 | M4: 185.58 | N4: 34 | O4: Male | P4: Debit Card
A5: 101130 | B5: 45096 | C5: AD-6222-A | D5: Adilette Slides | E5: Footwear | F5: Oman | G5: Outlet | H5: 3 | I5: 31 | J5: 0 | K5: 93 | L5: 28.22 | M5: 84.66 | N5: 34 | O5: Male | P5: NetBanking
A6: 101044 | B6: 45640 | C6: AD-7512-D | D6: Predator Freak | E6: Footwear | F6: Lebanon | G6: Online | H6: 2 | I6: 220.12 | J6: 5 | K6: 418.23 | L6: 108.68 | M6: 217.36 | N6: 36 | O6: Female | P6: UPI
A7: 100330 | B7: 45262 | C7: AD-4974-D | D7: Superstar | E7: Footwear | F7: Iraq | G7: Online | H7: 4 | I7: 95.63 | J7: 0 | K7: 382.52 | L7: 105.82 | M7: 423.28 | N7: 32 | O7: Female | P7: NetBanking
A8: 100323 | B8: 45049 | C8: AD-3735-C | D8: Ultraboost 22 | E8: Footwear | F8: Egypt | G8: Online | H8: 4 | I8: 182.16 | J8: 0 | K8: 728.64 | L8: 227.81 | M8: 911.24 | N8: 29 | O8: Female | P8: NetBanking
A9: 100087 | B9: 45708 | C9: AD-9056-A | D9: Copa Sense | E9: Footwear | F9: Egypt | G9: Outlet | H9: 2 | I9: 149.85 | J9: 5 | K9: 284.71 | L9: 83.89 | M9: 167.78 | N9: 21 | O9: Male | P9: Apple Pay
A10: 100411 | B10: 45229 | C10: AD-4842-A | D10: Copa Sense | E10: Footwear | F10: Oman | G10: Online | H10: 3 | I10: 152.09 | J10: 10 | K10: 410.64 | L10: 93.96 | M10: 281.88 | N10: 27 | O10: Female | P10: Cash
A11: 101123 | B11: 45861 | C11: AD-4445-D | D11: Adilette Slides | E11: Footwear | F11: Oman | G11: Online | H11: 3 | I11: 33.9 | J11: 5 | K11: 96.61 | L11: 33.52 | M11: 100.56 | N11: 20 | O11: Male | P11: Debit Card
A12: 100871 | B12: 45774 | C12: AD-3044-D | D12: NMD_R1 | E12: Footwear | F12: Iraq | G12: Retail | H12: 5 | I12: 127.61 | J12: 5 | K12: 606.15 | L12: 149.27 | M12: 746.35 | N12: 30 | O12: Female | P12: Credit Card
A13: 100769 | B13: 45643 | C13: AD-6947-D | D13: Stan Smith | E13: Footwear | F13: Oman | G13: Retail | H13: 3 | I13: 79.71 | J13: 5 | K13: 227.17 | L13: 58.6 | M13: 175.8 | N13: 35 | O13: Female | P13: PayPal
... A503: 100436 | B503: 45654 | C503: AD-9747-C | D503: Stan Smith | E503: Footwear | F503: Egypt | G503: Retail | H503: 3 | I503: 89.53 | J503: 0 | K503: 268.59 | L503: 86.24 | M503: 258.72 | N503: 19 | O503: Female | P503: Apple Pay

Sheet Sheet2
A1: Order_ID | B1: Order_Date | C1: SKU | D1: Product_Name | E1: Category | F1: Region | G1: Store_Type | H1: Units_Sold | I1: Unit_Price | J1: Discount | K1: Revenue | L1: Profit | M1: Total Profit | N1: Customer_Age | O1: Gender | P1: Payment_Method
A2: 101126 | B2: 45875 | C2: AD-4543-C | D2: Stan Smith | E2: Footwear | F2: Iraq | G2: Online | H2: 6 | I2: 72.03 | J2: 20 | K2: 345.74 | L2: 94.24 | M2: 565.44 | N2: 31 | O2: Male | P2: PayPal
A3: 100860 | B3: 45172 | C3: AD-5412-A | D3: NMD_R1 | E3: Footwear | F3: Oman | G3: Retail | H3: 4 | I3: 142.77 | J3: 0 | K3: 571.08 | L3: 170.99 | M3: 683.96 | N3: 40 | O3: Male | P3: Debit Card
A4: 100101 | B4: 45559 | C4: AD-8110-A | D4: Superstar | E4: Footwear | F4: Egypt | G4: Online | H4: 3 | I4: 96.58 | J4: 20 | K4: 231.79 | L4: 61.86 | M4: 185.58 | N4: 34 | O4: Male | P4: Debit Card
A5: 101130 | B5: 45096 | C5: AD-6222-A | D5: Adilette Slides | E5: Footwear | F5: Oman | G5: Outlet | H5: 3 | I5: 31 | J5: 0 | K5: 93 | L5: 28.22 | M5: 84.66 | N5: 34 | O5: Male | P5: NetBanking
A6: 101044 | B6: 45640 | C6: AD-7512-D | D6: Predator Freak | E6: Footwear | F6: Lebanon | G6: Online | H6: 2 | I6: 220.12 | J6: 5 | K6: 418.23 | L6: 108.68 | M6: 217.36 | N6: 36 | O6: Female | P6: UPI
A7: 100330 | B7: 45262 | C7: AD-4974-D | D7: Superstar | E7: Footwear | F7: Iraq | G7: Online | H7: 4 | I7: 95.63 | J7: 0 | K7: 382.52 | L7: 105.82 | M7: 423.28 | N7: 32 | O7: Female | P7: NetBanking
A8: 100323 | B8: 45049 | C8: AD-3735-C | D8: Ultraboost 22 | E8: Footwear | F8: Egypt | G8: Online | H8: 4 | I8: 182.16 | J8: 0 | K8: 728.64 | L8: 227.81 | M8: 911.24 | N8: 29 | O8: Female | P8: NetBanking
A9: 100087 | B9: 45708 | C9: AD-9056-A | D9: Copa Sense | E9: Footwear | F9: Egypt | G9: Outlet | H9: 2 | I9: 149.85 | J9: 5 | K9: 284.71 | L9: 83.89 | M9: 167.78 | N9: 21 | O9: Male | P9: Apple Pay
A10: 100411 | B10: 45229 | C10: AD-4842-A | D10: Copa Sense | E10: Footwear | F10: Oman | G10: Online | H10: 3 | I10: 152.09 | J10: 10 | K10: 410.64 | L10: 93.96 | M10: 281.88 | N10: 27 | O10: Female | P10: Cash
A11: 101123 | B11: 45861 | C11: AD-4445-D | D11: Adilette Slides | E11: Footwear | F11: Oman | G11: Online | H11: 3 | I11: 33.9 | J11: 5 | K11: 96.61 | L11: 33.52 | M11: 100.56 | N11: 20 | O11: Male | P11: Debit Card
A12: 100871 | B12: 45774 | C12: AD-3044-D | D12: NMD_R1 | E12: Footwear | F12: Iraq | G12: Retail | H12: 5 | I12: 127.61 | J12: 5 | K12: 606.15 | L12: 149.27 | M12: 746.35 | N12: 30 | O12: Female | P12: Credit Card
A13: 100769 | B13: 45643 | C13: AD-6947-D | D13: Stan Smith | E13: Footwear | F13: Oman | G13: Retail | H13: 3 | I13: 79.71 | J13: 5 | K13: 227.17 | L13: 58.6 | M13: 175.8 | N13: 35 | O13: Female | P13: PayPal
... A503: 100436 | B503: 45654 | C503: AD-9747-C | D503: Stan Smith | E503: Footwear | F503: Egypt | G503: Retail | H503: 3 | I503: 89.53 | J503: 0 | K503: 268.59 | L503: 86.24 | M503: 258.72 | N503: 19 | O503: Female | P503: Apple Pay

Sheet Sheet3
A1: Order_ID | B1: Order_Date | C1: SKU | D1: Product_Name | E1: Category | F1: Region | G1: Store_Type | H1: Units_Sold | I1: Unit_Price | J1: Discount | K1: Revenue | L1: Profit | M1: Total Profit | N1: Customer_Age | O1: Gender | P1: Payment_Method
A2: 101126 | B2: 45875 | C2: AD-4543-C | D2: Stan Smith | E2: Footwear | F2: Iraq | G2: Online | H2: 6 | I2: 72.03 | J2: 20 | K2: 345.74 | L2: 94.24 | M2: 565.44 | N2: 31 | O2: Male | P2: PayPal
A3: 100860 | B3: 45172 | C3: AD-5412-A | D3: NMD_R1 | E3: Footwear | F3: Oman | G3: Retail | H3: 4 | I3: 142.77 | J3: 0 | K3: 571.08 | L3: 170.99 | M3: 683.96 | N3: 40 | O3: Male | P3: Debit Card
A4: 100101 | B4: 45559 | C4: AD-8110-A | D4: Superstar | E4: Footwear | F4: Egypt | G4: Online | H4: 3 | I4: 96.58 | J4: 20 | K4: 231.79 | L4: 61.86 | M4: 185.58 | N4: 34 | O4: Male | P4: Debit Card
A5: 101130 | B5: 45096 | C5: AD-6222-A | D5: Adilette Slides | E5: Footwear | F5: Oman | G5: Outlet | H5: 3 | I5: 31 | J5: 0 | K5: 93 | L5: 28.22 | M5: 84.66 | N5: 34 | O5: Male | P5: NetBanking
A6: 101044 | B6: 45640 | C6: AD-7512-D | D6: Predator Freak | E6: Footwear | F6: Lebanon | G6: Online | H6: 2 | I6: 220.12 | J6: 5 | K6: 418.23 | L6: 108.68 | M6: 217.36 | N6: 36 | O6: Female | P6: UPI
A7: 100330 | B7: 45262 | C7: AD-4974-D | D7: Superstar | E7: Footwear | F7: Iraq | G7: Online | H7: 4 | I7: 95.63 | J7: 0 | K7: 382.52 | L7: 105.82 | M7: 423.28 | N7: 32 | O7: Female | P7: NetBanking
A8: 100323 | B8: 45049 | C8: AD-3735-C | D8: Ultraboost 22 | E8: Footwear | F8: Egypt | G8: Online | H8: 4 | I8: 182.16 | J8: 0 | K8: 728.64 | L8: 227.81 | M8: 911.24 | N8: 29 | O8: Female | P8: NetBanking
A9: 100087 | B9: 45708 | C9: AD-9056-A | D9: Copa Sense | E9: Footwear | F9: Egypt | G9: Outlet | H9: 2 | I9: 149.85 | J9: 5 | K9: 284.71 | L9: 83.89 | M9: 167.78 | N9: 21 | O9: Male | P9: Apple Pay
A10: 100411 | B10: 45229 | C10: AD-4842-A | D10: Copa Sense | E10: Footwear | F10: Oman | G10: Online | H10: 3 | I10: 152.09 | J10: 10 | K10: 410.64 | L10: 93.96 | M10: 281.88 | N10: 27 | O10: Female | P10: Cash
A11: 101123 | B11: 45861 | C11: AD-4445-D | D11: Adilette Slides | E11: Footwear | F11: Oman | G11: Online | H11: 3 | I11: 33.9 | J11: 5 | K11: 96.61 | L11: 33.52 | M11: 100.56 | N11: 20 | O11: Male | P11: Debit Card
A12: 100871 | B12: 45774 | C12: AD-3044-D | D12: NMD_R1 | E12: Footwear | F12: Iraq | G12: Retail | H12: 5 | I12: 127.61 | J12: 5 | K12: 606.15 | L12: 149.27 | M12: 746.35 | N12: 30 | O12: Female | P12: Credit Card
A13: 100769 | B13: 45643 | C13: AD-6947-D | D13: Stan Smith | E13: Footwear | F13: Oman | G13: Retail | H13: 3 | I13: 79.71 | J13: 5 | K13: 227.17 | L13: 58.6 | M13: 175.8 | N13: 35 | O13: Female | P13: PayPal
... A503: 100436 | B503: 45654 | C503: AD-9747-C | D503: Stan Smith | E503: Footwear | F503: Egypt | G503: Retail | H503: 3 | I503: 89.53 | J503: 0 | K503: 268.59 | L503: 86.24 | M503: 258.72 | N503: 19 | O503: Female | P503: Apple Pay

Sheet Sheet4
A1: Order_ID | B1: Order_Date | C1: SKU | D1: Product_Name | E1: Category | F1: Region | G1: Store_Type | H1: Units_Sold | I1: Unit_Price | J1: Discount | K1: Revenue | L1: Profit | M1: Total Profit | N1: Customer_Age | O1: Gender | P1: Payment_Method
A2: 100021 | B2: 45289 | C2: AD-1993-D | D2: Originals Backpack | E2: Accessories | F2: KSA | G2: Online | H2: 2 | I2: 59.87 | J2: 5 | K2: 113.75 | L2: 38.02 | M2: 76.04 | N2: 49 | O2: Female | P2: Debit Card
A3: 100699 | B3: 45408 | C3: AD-4085-D | D3: Sports Bottle | E3: Accessories | F3: Oman | G3: Online | H3: 4 | I3: 15.21 | J3: 0 | K3: 60.84 | L3: 25.41 | M3: 101.64 | N3: 26 | O3: Female | P3: Debit Card
A4: 100161 | B4: 45243 | C4: AD-8564-C | D4: Training Cap | E4: Accessories | F4: Iraq | G4: Retail | H4: 3 | I4: 19.93 | J4: 0 | K4: 59.79 | L4: 17.42 | M4: 52.26 | N4: 35 | O4: Female | P4: Google Pay
A5: 100439 | B5: 45294 | C5: AD-4892-C | D5: Performance Socks (3-pack) | E5: Accessories | F5: KSA | G5: Retail | H5: 5 | I5: 17.49 | J5: 10 | K5: 78.7 | L5: 35.99 | M5: 179.95 | N5: 30 | O5: Female | P5: Apple Pay
A6: 100058 | B6: 45206 | C6: AD-8657-B | D6: Originals Backpack | E6: Accessories | F6: Oman | G6: Retail | H6: 3 | I6: 58.96 | J6: 5 | K6: 168.04 | L6: 68.38 | M6: 205.14 | N6: 30 | O6: Female | P6: PayPal
A7: 100815 | B7: 44947 | C7: AD-6469-A | D7: Performance Socks (3-pack) | E7: Accessories | F7: Iraq | G7: Retail | H7: 4 | I7: 17.84 | J7: 0 | K7: 71.36 | L7: 26.79 | M7: 107.16 | N7: 34 | O7: Female | P7: Credit Card
A8: 100216 | B8: 45873 | C8: AD-5450-B | D8: Performance Socks (3-pack) | E8: Accessories | F8: Egypt | G8: Online | H8: 4 | I8: 18.86 | J8: 0 | K8: 75.44 | L8: 28.6 | M8: 114.4 | N8: 28 | O8: Female | P8: NetBanking
A9: 100974 | B9: 45283 | C9: AD-7305-C | D9: Originals Backpack | E9: Accessories | F9: Lebanon | G9: Retail | H9: 3 | I9: 57.19 | J9: 0 | K9: 171.57 | L9: 52.43 | M9: 157.29 | N9: 49 | O9: Female | P9: Debit Card
A10: 100187 | B10: 45490 | C10: AD-6922-B | D10: Sports Bottle | E10: Accessories | F10: Iraq | G10: Online | H10: 3 | I10: 14.94 | J10: 5 | K10: 42.58 | L10: 21.21 | M10: 63.63 | N10: 29 | O10: Female | P10: PayPal
A11: 100379 | B11: 45690 | C11: AD-6094-C | D11: Training Cap | E11: Accessories | F11: KSA | G11: Online | H11: 2 | I11: 23.11 | J11: 0 | K11: 46.22 | L11: 15.51 | M11: 31.02 | N11: 30 | O11: Female | P11: NetBanking
A12: 100064 | B12: 45037 | C12: AD-4249-A | D12: Running Watch Strap | E12: Accessories | F12: Oman | G12: Retail | H12: 1 | I12: 38.49 | J12: 10 | K12: 34.64 | L12: 11.99 | M12: 11.99 | N12: 39 | O12: Female | P12: Apple Pay
A13: 101086 | B13: 45415 | C13: AD-2528-B | D13: Running Watch Strap | E13: Accessories | F13: Iraq | G13: Online | H13: 5 | I13: 41.63 | J13: 0 | K13: 208.15 | L13: 59.23 | M13: 296.15 | N13: 45 | O13: Female | P13: Debit Card
... A152: 101102 | B152: 45284 | C152: AD-6811-D | D152: Originals Backpack | E152: Accessories | F152: Oman | G152: Retail | H152: 3 | I152: 62.34 | J152: 5 | K152: 177.67 | L152: 80.61 | M152: 241.83 | N152: 16 | O152: Female | P152: Apple Pay

Sheet Pivot Tables
A2: Sales Performance | P2: Profitability | U2: Trends & Growth | Z2: Product Analysis | AF2: Regional Analysis
A4: Sum of Units_Sold | B4: Column Labels | H4: STORE TYPE | I4: Sum of Units_Sold | K4: Row Labels | L4: Sum of Profit | M4: Sum of Total Sales | P4: Row Labels | Q4: Sum of Profit | S4: Sum of Profit | U4: Row Labels | V4: Sum of Total Sales | Z4: Row Labels | AA4: Sum of Total Sales | AF4: Row Labels | AG4: Sum of Profit | AH4: Sum of Total Sales
A5: Row Labels | B5: Online | C5: Outlet | D5: Retail | E5: Wholesale | F5: Grand Total | H5: Online | I5: 0.45098592 | K5: Predator Freak | L5: 9218.42 | M5: 31599.08 | P5: Egypt | Q5: 25519.31 | S5: 85069.85 | U5: 2023 | V5: 107348.43 | Z5: Accessories | AA5: 30994.47 | AF5: Egypt | AG5: 25519.31 | AH5: 86027.88
A6: 2023 | B6: 555 | C6: 159 | D6: 506 | E6: 95 | F6: 1315 | H6: Retail | I6: 0.35577465 | K6: Ultraboost Light | L6: 8876.32 | M6: 30192.09 | P6: Iraq | Q6: 24051.61 | U6: Jan | V6: 8841.15 | Z6: Gym Bag | AA6: 3971.53 | AF6: Iraq | AG6: 24051.61 | AH6: 81724.56
A7: 2024 | B7: 634 | C7: 147 | D7: 438 | E7: 94 | F7: 1313 | H7: Outlet | I7: 0.12028169 | K7: Copa Sense | L7: 8086.74 | M7: 27178.45 | P7: KSA | Q7: 9846.85 | U7: Feb | V7: 4211.32 | Z7: Originals Backpack | AA7: 10172.12 | AF7: KSA | AG7: 9846.85 | AH7: 32966.34
A8: 2025 | B8: 412 | C8: 121 | D8: 319 | E8: 70 | F8: 922 | H8: Wholesale | I8: 0.072957746 | K8: Primegreen Jacket | L8: 7687.4 | M8: 27720.09 | P8: Lebanon | Q8: 5248.52 | U8: Mar | V8: 7985.01 | Z8: Performance Socks (3-pack) | AA8: 3339.71 | AF8: Lebanon | AG8: 5248.52 | AH8: 17601.98
A9: Grand Total | B9: 1601 | C9: 427 | D9: 1263 | E9: 259 | F9: 3550 | H9: Grand Total | I9: 1 | K9: Ultraboost 22 | L9: 7680.82 | M9: 25555.62 | P9: Oman | Q9: 20403.56 | U9: Apr | V9: 12515.29 | Z9: Running Watch Strap | AA9: 6956.86 | AF9: Oman | AG9: 20403.56 | AH9: 69057.16
K10: Z.N.E. Hoodie | L10: 7070.1 | M10: 24288.03 | P10: Grand Total | Q10: 85069.85 | U10: May | V10: 9064.79 | Z10: Sports Bottle | AA10: 2581.61 | AF10: Grand Total | AG10: 85069.85 | AH10: 287377.92
K11: NMD_R1 | L11: 5832.62 | M11: 19746.08 | U11: Jun | V11: 7146.25 | Z11: Training Cap | AA11: 3972.64
K12: Superstar | L12: 5727.72 | M12: 19507.31 | U12: Jul | V12: 8782.35 | Z12: Apparel | AA12: 77377.83
K13: Stan Smith | L13: 5661.57 | M13: 19473.91 | U13: Aug | V13: 8107.39 | Z13: Adicolor Hoodie | AA13: 10080.65
K14: Originals Backpack | L14: 3354.68 | M14: 10172.12 | U14: Sep | V14: 9372.61 | Z14: Essentials Tee | AA14: 3033.24
K15: Grand Total | L15: 69196.39 | M15: 235432.78 | U15: Oct | V15: 12775.49 | Z15: Primegreen Jacket | AA15: 27720.09
U16: Nov | V16: 8672.51 | Z16: Tiro 23 Track Pants | AA16: 7427.35
H17: TOTAL SOLD UNITS | U17: Dec | V17: 9874.27 | Z17: Training Shorts | AA17: 4828.47
H18: 3550 | U18: 2024 | V18: 103229.75 | Z18: Z.N.E. Hoodie | AA18: 24288.03
U19: Jan | V19: 10026.96 | Z19: Footwear | AA19: 179005.62
H20: Sum of Total Sales | U20: Feb | V20: 6106.71 | Z20: Adilette Slides | AA20: 5753.08
H21: 287377.92 | U21: Mar | V21: 12667.48 | Z21: Copa Sense | AA21: 27178.45
U22: Apr | V22: 5660.27 | Z22: NMD_R1 | AA22: 19746.08
U23: May | V23: 11431.88 | Z23: Predator Freak | AA23: 31599.08
U24: Jun | V24: 8589.02 | Z24: Stan Smith | AA24: 19473.91
U25: Jul | V25: 7167.15 | Z25: Superstar | AA25: 19507.31
U26: Aug | V26: 7369.32 | Z26: Ultraboost 22 | AA26: 25555.62
P27: Row Labels | Q27: Sum of Total Sales | U27: Sep | V27: 7961.61 | Z27: Ultraboost Light | AA27: 30192.09
P28: Egypt | Q28: 86027.88 | U28: Oct | V28: 7454.29 | Z28: Grand Total | AA28: 287377.92
P29: Iraq | Q29: 81724.56 | U29: Nov | V29: 7457.03
P30: KSA | Q30: 32966.34 | U30: Dec | V30: 11338.03
P31: Lebanon | Q31: 17601.98 | U31: 2025 | V31: 76799.74
P32: Oman | Q32: 69057.16 | U32: Jan | V32: 7163.28
P33: Grand Total | Q33: 287377.92 | U33: Feb | V33: 8547.43
U34: Mar | V34: 8990.68
U35: Apr | V35: 7592.4
U36: May | V36: 9179.6
U37: Jun | V37: 9746.06
U38: Jul | V38: 6539.32
U39: Aug | V39: 8158.16
U40: Sep | V40: 10882.81
U41: Grand Total | V41: 287377.92
K43: Pareto (80/20) Analysis
...

Sheet Dashboard
F7: Total Sales | G7: =GETPIVOTDATA("Total Sales",'Pivot Tables'!$H$20) -> 287377.92 | I7: Total Profit | J7: =GETPIVOTDATA("Profit",'Pivot Tables'!$S$4) -> 85069.85 | L7: Units Sold | M7: =GETPIVOTDATA("Units_Sold",'Pivot Tables'!$H$17) -> 3550 | O7: Profit Margin % | P7: =J7/G7 -> 0.29602083 | R7: YoY Sales growth % | S7: =(GETPIVOTDATA("Total Sales",'Pivot Tables'!$U$4,"Years",2025)-GETPIVOTDATA("Total Sales",'Pivot Tables'!$U$4,"Years",2024))/GETPIVOTDATA("Total Sales",'Pivot Tables'!$U$4,"Years",2024) -> -0.25603094 | U7: YoY Proit growth % | V7: =(GETPIVOTDATA("Profit",'Pivot Tables'!$U$49,"Years",2025)-GETPIVOTDATA("Profit",'Pivot Tables'!$U$49,"Years",2024))/GETPIVOTDATA("Profit",'Pivot Tables'!$U$49,"Years",2024) -> -0.24689912
